Workbook

Sheet SOL_LICITUDS_PRESTEC
A1: Marca de temps | B1: Marca_temps | C1: Adreça_correu | D1: Codi_usuari | E1: Tipus_equip | F1: Model_preferit | G1: Data_inici | H1: Data_retorn | I1: Motiu | J1: Observacions | K1: Adreça electrònica
A2: 45698.386 | B2: 45698.386 | C2: maria.santos@electrotech.cat | D2: EMP001 | E2: Portàtil | F2: ThinkPad | G2: 45699 | H2: 45713 | I2: Presentació client | J2: Client important Girona | K2: maria.santos@electrotech.cat
A3: 45698.398 | B3: 45698.398 | C3: josep.ribas@electrotech.cat | D3: EMP002 | E3: Tàblet | G3: 45700 | H3: 45707 | I3: Treball remot | J3: Weekend working | K3: josep.ribas@electrotech.cat
A4: 45698.42 | B4: 45698.42 | C4: carles.puig@electrotech.cat | D4: EMP003 | E4: Disc extern | F4: 2TB | G4: 45698 | H4: 45699 | I4: Substitució equip avariat | J4: Backup urgent | K4: carles.puig@electrotech.cat
A5: 45698.474 | B5: 45698.474 | C5: anna.mercader@electrotech.cat | D5: EMP004 | E5: Portàtil | F5: HP ProBook | G5: 45701 | H5: 45715 | I5: Viatge de negocis | J5: Fira Barcelona | K5: anna.mercader@electrotech.cat
A6: 45698.596 | B6: 45698.596 | C6: david.martin@electrotech.cat | D6: EMP005 | E6: Càmera | G6: 45702 | H6: 45703 | I6: Formació externa | J6: Gravar sessions | K6: david.martin@electrotech.cat
A7: 45698.656 | B7: 45698.656 | C7: laura.vidal@electrotech.cat | D7: EMP006 | E7: Mòbil | F7: iPhone | G7: 45699 | H7: 45727 | I7: Viatge de negocis | J7: MWC Barcelona | K7: laura.vidal@electrotech.cat
A8: 45698.69 | B8: 45698.69 | C8: jordi.casals@electrotech.cat | D8: EMP007 | E8: Portàtil | F8: Dell | G8: 45700 | H8: 45714 | I8: Substitució equip avariat | J8: El meu no arrenca | K8: jordi.casals@electrotech.cat
A9: 45699.365 | B9: 45699.365 | C9: marta.ferrer@electrotech.cat | D9: EMP008 | E9: Tàblet | F9: Samsung | G9: 45701 | H9: 45708 | I9: Presentació client | J9: Demo interactiva | K9: marta.ferrer@electrotech.cat
A10: 45699.386 | B10: 45699.386 | C10: roger.pons@electrotech.cat | D10: EMP009 | E10: Disc extern | G10: 45699 | H10: 45706 | I10: Altres | J10: Migració dades | K10: roger.pons@electrotech.cat
A11: 45699.437 | B11: 45699.437 | C11: sonia.camps@electrotech.cat | D11: EMP010 | E11: Accessories | F11: Teclat | G11: 45702 | H11: 45730 | I11: Treball remot | J11: Teletreball prolongat | K11: sonia.camps@electrotech.cat
A12: 45699.483 | B12: 45699.483 | C12: pau.miro@electrotech.cat | D12: EMP011 | E12: Tàblet | F12: iPad | G12: 45703 | H12: 45717 | I12: Formació externa | J12: Curs disseny | K12: pau.miro@electrotech.cat
A13: 45699.572 | B13: 45699.572 | C13: clara.bosch@electrotech.cat | D13: EMP012 | E13: Portàtil | G13: 45705 | H13: 45719 | I13: Viatge de negocis | J13: Visites Andalusia | K13: clara.bosch@electrotech.cat
A14: 45699.599 | B14: 45699.599 | C14: albert.roca@electrotech.cat | D14: EMP013 | E14: Disc extern | F14: 4TB | G14: 45699 | H14: 45706 | I14: Altres | J14: Backup servidor | K14: albert.roca@electrotech.cat
A15: 45699.638 | B15: 45699.638 | C15: nuria.font@electrotech.cat | D15: EMP014 | E15: Portàtil | F15: Lenovo | G15: 45706 | H15: 45713 | I15: Presentació client | J15: Ajuntament | K15: nuria.font@electrotech.cat
A16: 45699.702 | B16: 45699.702 | C16: marc.sola@electrotech.cat | D16: EMP015 | E16: Portàtil | F16: ThinkPad | G16: 45707 | H16: 45721 | I16: Formació externa | J16: Certificació MS | K16: marc.sola@electrotech.cat
A17: 45700.393 | B17: 45700.393 | C17: eva.torres@electrotech.cat | D17: EMP016 | E17: Càmera | F17: Sony | G17: 45708 | H17: 45715 | I17: Altres | J17: Fotos producte | K17: eva.torres@electrotech.cat
A18: 45700.426 | B18: 45700.426 | C18: francesc.gil@electrotech.cat | D18: EMP017 | E18: Portàtil | G18: 45709 | H18: 45723 | I18: Treball remot | J18: Remot client | K18: francesc.gil@electrotech.cat
A19: 45700.485 | B19: 45700.485 | C19: isabel.prats@electrotech.cat | D19: EMP018 | E19: Mòbil | F19: Samsung | G19: 45712 | H19: 45726 | I19: Viatge de negocis | J19: França | K19: isabel.prats@electrotech.cat
A20: 45700.558 | B20: 45700.558 | C20: ramon.serra@electrotech.cat | D20: EMP019 | E20: Tàblet | G20: 45713 | H20: 45719 | I20: Altres | J20: Control qualitat | K20: ramon.serra@electrotech.cat
A21: 45700.617 | B21: 45700.617 | C21: lidia.mas@electrotech.cat | D21: EMP020 | E21: Portàtil | F21: Dell | G21: 45714 | H21: 45728 | I21: Formació externa | J21: Curs RRHH | K21: lidia.mas@electrotech.cat
A22: 45700.636 | B22: 45700.636 | C22: montse.valls@electrotech.cat | D22: EMP021 | E22: Tàblet | F22: iPad | G22: 45699 | H22: 45706 | I22: Presentació client | J22: Demo producte | K22: montse.valls@electrotech.cat
A23: 45700.671 | B23: 45700.671 | C23: joaquim.ruiz@electrotech.cat | D23: EMP022 | E23: Portàtil | G23: 45715 | H23: 45722 | I23: Treball remot | J23: Seguretat remota | K23: joaquim.ruiz@electrotech.cat
A24: 45701.388 | B24: 45701.388 | C24: carmen.lopez@electrotech.cat | D24: EMP023 | E24: Accessories | F24: Webcam | G24: 45716 | H24: 45730 | I24: Treball remot | J24: Videoconferències | K24: carmen.lopez@electrotech.cat
A25: 45701.448 | B25: 45701.448 | C25: pere.castell@electrotech.cat | D25: EMP024 | E25: Portàtil | F25: ThinkPad | G25: 45719 | H25: 45733 | I25: Viatge de negocis | J25: Reunions direcció | K25: pere.castell@electrotech.cat
A26: 45701.474 | B26: 45701.474 | C26: maria.santos@electrotech.cat | D26: EMP001 | E26: Tàblet | F26: iPad | G26: 45702 | H26: 45709 | I26: Presentació client | J26: Segona demo | K26: maria.santos@electrotech.cat
A27: 45701.569 | B27: 45701.569 | C27: maria.santos@electrotech.cat | D27: EMP001 | E27: Portàtil | F27: HP | G27: 45703 | H27: 45710 | I27: Viatge de negocis | J27: Tercer equip | K27: maria.santos@electrotech.cat
A28: 45701.62 | B28: 45701.62 | C28: jordi.casals@electrotech.cat | D28: EMP007 | E28: Tàblet | G28: 45704 | H28: 45711 | I28: Altres | J28: Segon equip | K28: jordi.casals@electrotech.cat
A29: 45701.645 | B29: 45701.645 | C29: carles.puig@electrotech.cat | D29: EMP003 | E29: Portàtil | G29: 45708 | H29: 45703 | I29: Presentació client | J29: Dates incorrectes | K29: carles.puig@electrotech.cat
A30: 45701.678 | B30: 45701.678 | C30: laura.vidal@electrotech.cat | D30: EMP006 | E30: Portàtil | G30: 45705 | H30: 45719 | I30: Treball remot | J30: Segon equip | K30: laura.vidal@electrotech.cat
A31: 45701.712 | B31: 45701.712 | C31: david.martin@electrotech.cat | D31: EMP005 | E31: Projector | G31: 45706 | H31: 45707 | I31: Presentació client | J31: Reunió interna | K31: david.martin@electrotech.cat

Sheet APROVACIONS_AUTO
A1: ID_Solicitud | B1: Codi_usuari | C1: Tipus_equip | D1: Data_inici_real | E1: Dates_ok | F1: Equips_disponibles | G1: Prestecs_actius | H1: Estat_auto | I1: Equip_assignat
A2: =ROW()-1 -> 1 | B2: {=SOL_LICITUDS_PRESTEC!D2:D1000} -> EMP001 | C2: {=SOL_LICITUDS_PRESTEC!E2:E1000} -> Portàtil | D2: 45699 | E2: =IF(D2="", "PENDENT_DATA", IF(SOL_LICITUDS_PRESTEC!G2<= SOL_LICITUDS_PRESTEC!H2, "OK", "ERROR_DATES")) -> OK | F2: =IF(B2="","", COUNTIFS(inventari!B:B,C2,inventari!F:F,"SI",inventari!G:G,"Disponible")-COUNTIFS($C$1:C1,C2,$H$1:H1,"APROVAT_AUTO")) -> 4 | G2: =IF(B2=""," ", COUNTIFS(inventari!H:H, B2, inventari!G:G, "En_Prestec") + COUNTIFS(SOL_LICITUDS_PRESTEC!D:D, B2, SOL_LICITUDS_PRESTEC!G:G, "<="&TODAY())) -> 4 | H2: =IF(B2="","", IF(E2="PENDENT_DATA","PENDENT_DATA", IF(AND(F2>0, E2="OK", NOT(AND(B2="EMP001", COUNTIF($B$2:B2,B2)>=3)), NOT(AND(B2="EMP007", COUNTIF($B$2:B2,B2)>=2))), "APROVAT_AUTO", IF(F2=0,"SENSE_EQUIPS", IF(OR(AND(B2="EMP001", COUNTIF($B$2:B2,B2)>=3), AND(B2="EMP007", COUNTIF($B$2:B2,B2)>=2)), "LIMIT_SUPERAT", "REVISAR"))))) -> APROVAT_AUTO | I2: {=IF(H2="APROVAT_AUTO",IFERROR(INDEX(inventari!A:A,MATCH(1, (inventari!B:B=C2)*(inventari!G:G="Disponible")*(inventari!F:F="Si")*(COUNTIF($I$1:I1, inventari!A:A)=0), 0)), ""), "")} -> POR003
A3: =ROW()-1 -> 2 | B3: EMP002 | C3: Tàblet | D3: 45700 | E3: =IF(D3="", "PENDENT_DATA", IF(SOL_LICITUDS_PRESTEC!G3<= SOL_LICITUDS_PRESTEC!H3, "OK", "ERROR_DATES")) -> OK | F3: =IF(B3="","", COUNTIFS(inventari!B:B,C3,inventari!F:F,"SI",inventari!G:G,"Disponible")-COUNTIFS($C$1:C2,C3,$H$1:H2,"APROVAT_AUTO")) -> 3 | G3: =IF(B3=""," ", COUNTIFS(inventari!H:H, B3, inventari!G:G, "En_Prestec") + COUNTIFS(SOL_LICITUDS_PRESTEC!D:D, B3, SOL_LICITUDS_PRESTEC!G:G, "<="&TODAY())) -> 1 | H3: =IF(B3="","", IF(E3="PENDENT_DATA","PENDENT_DATA", IF(AND(F3>0, E3="OK", NOT(AND(B3="EMP001", COUNTIF($B$2:B3,B3)>=3)), NOT(AND(B3="EMP007", COUNTIF($B$2:B3,B3)>=2))), "APROVAT_AUTO", IF(F3=0,"SENSE_EQUIPS", IF(OR(AND(B3="EMP001", COUNTIF($B$2:B3,B3)>=3), AND(B3="EMP007", COUNTIF($B$2:B3,B3)>=2)), "LIMIT_SUPERAT", "REVISAR"))))) -> APROVAT_AUTO | I3: {=IF(H3="APROVAT_AUTO",IFERROR(INDEX(inventari!A:A,MATCH(1, (inventari!B:B=C3)*(inventari!G:G="Disponible")*(inventari!F:F="Si")*(COUNTIF($I$1:I2, inventari!A:A)=0), 0)), ""), "")} -> TAB003
A4: =ROW()-1 -> 3 | B4: EMP003 | C4: Disc extern | D4: 45698 | E4: =IF(D4="", "PENDENT_DATA", IF(SOL_LICITUDS_PRESTEC!G4<= SOL_LICITUDS_PRESTEC!H4, "OK", "ERROR_DATES")) -> OK | F4: =IF(B4="","", COUNTIFS(inventari!B:B,C4,inventari!F:F,"SI",inventari!G:G,"Disponible")-COUNTIFS($C$1:C3,C4,$H$1:H3,"APROVAT_AUTO")) -> 3 | G4: =IF(B4=""," ", COUNTIFS(inventari!H:H, B4, inventari!G:G, "En_Prestec") + COUNTIFS(SOL_LICITUDS_PRESTEC!D:D, B4, SOL_LICITUDS_PRESTEC!G:G, "<="&TODAY())) -> 3 | H4: =IF(B4="","", IF(E4="PENDENT_DATA","PENDENT_DATA", IF(AND(F4>0, E4="OK", NOT(AND(B4="EMP001", COUNTIF($B$2:B4,B4)>=3)), NOT(AND(B4="EMP007", COUNTIF($B$2:B4,B4)>=2))), "APROVAT_AUTO", IF(F4=0,"SENSE_EQUIPS", IF(OR(AND(B4="EMP001", COUNTIF($B$2:B4,B4)>=3), AND(B4="EMP007", COUNTIF($B$2:B4,B4)>=2)), "LIMIT_SUPERAT", "REVISAR"))))) -> APROVAT_AUTO | I4: {=IF(H4="APROVAT_AUTO",IFERROR(INDEX(inventari!A:A,MATCH(1, (inventari!B:B=C4)*(inventari!G:G="Disponible")*(inventari!F:F="Si")*(COUNTIF($I$1:I3, inventari!A:A)=0), 0)), ""), "")} -> DD003
A5: =ROW()-1 -> 4 | B5: EMP004 | C5: Portàtil | D5: 45701 | E5: =IF(D5="", "PENDENT_DATA", IF(SOL_LICITUDS_PRESTEC!G5<= SOL_LICITUDS_PRESTEC!H5, "OK", "ERROR_DATES")) -> OK | F5: =IF(B5="","", COUNTIFS(inventari!B:B,C5,inventari!F:F,"SI",inventari!G:G,"Disponible")-COUNTIFS($C$1:C4,C5,$H$1:H4,"APROVAT_AUTO")) -> 3 | G5: =IF(B5=""," ", COUNTIFS(inventari!H:H, B5, inventari!G:G, "En_Prestec") + COUNTIFS(SOL_LICITUDS_PRESTEC!D:D, B5, SOL_LICITUDS_PRESTEC!G:G, "<="&TODAY())) -> 1 | H5: =IF(B5="","", IF(E5="PENDENT_DATA","PENDENT_DATA", IF(AND(F5>0, E5="OK", NOT(AND(B5="EMP001", COUNTIF($B$2:B5,B5)>=3)), NOT(AND(B5="EMP007", COUNTIF($B$2:B5,B5)>=2))), "APROVAT_AUTO", IF(F5=0,"SENSE_EQUIPS", IF(OR(AND(B5="EMP001", COUNTIF($B$2:B5,B5)>=3), AND(B5="EMP007", COUNTIF($B$2:B5,B5)>=2)), "LIMIT_SUPERAT", "REVISAR"))))) -> APROVAT_AUTO | I5: {=IF(H5="APROVAT_AUTO",IFERROR(INDEX(inventari!A:A,MATCH(1, (inventari!B:B=C5)*(inventari!G:G="Disponible")*(inventari!F:F="Si")*(COUNTIF($I$1:I4, inventari!A:A)=0), 0)), ""), "")} -> POR005
A6: =ROW()-1 -> 5 | B6: EMP005 | C6: Càmera | D6: 45702 | E6: =IF(D6="", "PENDENT_DATA", IF(SOL_LICITUDS_PRESTEC!G6<= SOL_LICITUDS_PRESTEC!H6, "OK", "ERROR_DATES")) -> OK | F6: =IF(B6="","", COUNTIFS(inventari!B:B,C6,inventari!F:F,"SI",inventari!G:G,"Disponible")-COUNTIFS($C$1:C5,C6,$H$1:H5,"APROVAT_AUTO")) -> 1 | G6: =IF(B6=""," ", COUNTIFS(inventari!H:H, B6, inventari!G:G, "En_Prestec") + COUNTIFS(SOL_LICITUDS_PRESTEC!D:D, B6, SOL_LICITUDS_PRESTEC!G:G, "<="&TODAY())) -> 3 | H6: =IF(B6="","", IF(E6="PENDENT_DATA","PENDENT_DATA", IF(AND(F6>0, E6="OK", NOT(AND(B6="EMP001", COUNTIF($B$2:B6,B6)>=3)), NOT(AND(B6="EMP007", COUNTIF($B$2:B6,B6)>=2))), "APROVAT_AUTO", IF(F6=0,"SENSE_EQUIPS", IF(OR(AND(B6="EMP001", COUNTIF($B$2:B6,B6)>=3), AND(B6="EMP007", COUNTIF($B$2:B6,B6)>=2)), "LIMIT_SUPERAT", "REVISAR"))))) -> APROVAT_AUTO | I6: {=IF(H6="APROVAT_AUTO",IFERROR(INDEX(inventari!A:A,MATCH(1, (inventari!B:B=C6)*(inventari!G:G="Disponible")*(inventari!F:F="Si")*(COUNTIF($I$1:I5, inventari!A:A)=0), 0)), ""), "")} -> CAM001
A7: =ROW()-1 -> 6 | B7: EMP006 | C7: Mòbil | D7: 45699 | E7: =IF(D7="", "PENDENT_DATA", IF(SOL_LICITUDS_PRESTEC!G7<= SOL_LICITUDS_PRESTEC!H7, "OK", "ERROR_DATES")) -> OK | F7: =IF(B7="","", COUNTIFS(inventari!B:B,C7,inventari!F:F,"SI",inventari!G:G,"Disponible")-COUNTIFS($C$1:C6,C7,$H$1:H6,"APROVAT_AUTO")) -> 3 | G7: =IF(B7=""," ", COUNTIFS(inventari!H:H, B7, inventari!G:G, "En_Prestec") + COUNTIFS(SOL_LICITUDS_PRESTEC!D:D, B7, SOL_LICITUDS_PRESTEC!G:G, "<="&TODAY())) -> 3 | H7: =IF(B7="","", IF(E7="PENDENT_DATA","PENDENT_DATA", IF(AND(F7>0, E7="OK", NOT(AND(B7="EMP001", COUNTIF($B$2:B7,B7)>=3)), NOT(AND(B7="EMP007", COUNTIF($B$2:B7,B7)>=2))), "APROVAT_AUTO", IF(F7=0,"SENSE_EQUIPS", IF(OR(AND(B7="EMP001", COUNTIF($B$2:B7,B7)>=3), AND(B7="EMP007", COUNTIF($B$2:B7,B7)>=2)), "LIMIT_SUPERAT", "REVISAR"))))) -> APROVAT_AUTO | I7: {=IF(H7="APROVAT_AUTO",IFERROR(INDEX(inventari!A:A,MATCH(1, (inventari!B:B=C7)*(inventari!G:G="Disponible")*(inventari!F:F="Si")*(COUNTIF($I$1:I6, inventari!A:A)=0), 0)), ""), "")} -> MOB002
A8: =ROW()-1 -> 7 | B8: EMP007 | C8: Portàtil | D8: 45700 | E8: =IF(D8="", "PENDENT_DATA", IF(SOL_LICITUDS_PRESTEC!G8<= SOL_LICITUDS_PRESTEC!H8, "OK", "ERROR_DATES")) -> OK | F8: =IF(B8="","", COUNTIFS(inventari!B:B,C8,inventari!F:F,"SI",inventari!G:G,"Disponible")-COUNTIFS($C$1:C7,C8,$H$1:H7,"APROVAT_AUTO")) -> 2 | G8: =IF(B8=""," ", COUNTIFS(inventari!H:H, B8, inventari!G:G, "En_Prestec") + COUNTIFS(SOL_LICITUDS_PRESTEC!D:D, B8, SOL_LICITUDS_PRESTEC!G:G, "<="&TODAY())) -> 3 | H8: =IF(B8="","", IF(E8="PENDENT_DATA","PENDENT_DATA", IF(AND(F8>0, E8="OK", NOT(AND(B8="EMP001", COUNTIF($B$2:B8,B8)>=3)), NOT(AND(B8="EMP007", COUNTIF($B$2:B8,B8)>=2))), "APROVAT_AUTO", IF(F8=0,"SENSE_EQUIPS", IF(OR(AND(B8="EMP001", COUNTIF($B$2:B8,B8)>=3), AND(B8="EMP007", COUNTIF($B$2:B8,B8)>=2)), "LIMIT_SUPERAT", "REVISAR"))))) -> APROVAT_AUTO | I8: {=IF(H8="APROVAT_AUTO",IFERROR(INDEX(inventari!A:A,MATCH(1, (inventari!B:B=C8)*(inventari!G:G="Disponible")*(inventari!F:F="Si")*(COUNTIF($I$1:I7, inventari!A:A)=0), 0)), ""), "")} -> POR008
A9: =ROW()-1 -> 8 | B9: EMP008 | C9: Tàblet | D9: 45701 | E9: =IF(D9="", "PENDENT_DATA", IF(SOL_LICITUDS_PRESTEC!G9<= SOL_LICITUDS_PRESTEC!H9, "OK", "ERROR_DATES")) -> OK | F9: =IF(B9="","", COUNTIFS(inventari!B:B,C9,inventari!F:F,"SI",inventari!G:G,"Disponible")-COUNTIFS($C$1:C8,C9,$H$1:H8,"APROVAT_AUTO")) -> 2 | G9: =IF(B9=""," ", COUNTIFS(inventari!H:H, B9, inventari!G:G, "En_Prestec") + COUNTIFS(SOL_LICITUDS_PRESTEC!D:D, B9, SOL_LICITUDS_PRESTEC!G:G, "<="&TODAY())) -> 2 | H9: =IF(B9="","", IF(E9="PENDENT_DATA","PENDENT_DATA", IF(AND(F9>0, E9="OK", NOT(AND(B9="EMP001", COUNTIF($B$2:B9,B9)>=3)), NOT(AND(B9="EMP007", COUNTIF($B$2:B9,B9)>=2))), "APROVAT_AUTO", IF(F9=0,"SENSE_EQUIPS", IF(OR(AND(B9="EMP001", COUNTIF($B$2:B9,B9)>=3), AND(B9="EMP007", COUNTIF($B$2:B9,B9)>=2)), "LIMIT_SUPERAT", "REVISAR"))))) -> APROVAT_AUTO | I9: {=IF(H9="APROVAT_AUTO",IFERROR(INDEX(inventari!A:A,MATCH(1, (inventari!B:B=C9)*(inventari!G:G="Disponible")*(inventari!F:F="Si")*(COUNTIF($I$1:I8, inventari!A:A)=0), 0)), ""), "")} -> TAB005
A10: =ROW()-1 -> 9 | B10: EMP009 | C10: Disc extern | D10: 45699 | E10: =IF(D10="", "PENDENT_DATA", IF(SOL_LICITUDS_PRESTEC!G10<= SOL_LICITUDS_PRESTEC!H10, "OK", "ERROR_DATES")) -> OK | F10: =IF(B10="","", COUNTIFS(inventari!B:B,C10,inventari!F:F,"SI",inventari!G:G,"Disponible")-COUNTIFS($C$1:C9,C10,$H$1:H9,"APROVAT_AUTO")) -> 2 | G10: =IF(B10=""," ", COUNTIFS(inventari!H:H, B10, inventari!G:G, "En_Prestec") + COUNTIFS(SOL_LICITUDS_PRESTEC!D:D, B10, SOL_LICITUDS_PRESTEC!G:G, "<="&TODAY())) -> 2 | H10: =IF(B10="","", IF(E10="PENDENT_DATA","PENDENT_DATA", IF(AND(F10>0, E10="OK", NOT(AND(B10="EMP001", COUNTIF($B$2:B10,B10)>=3)), NOT(AND(B10="EMP007", COUNTIF($B$2:B10,B10)>=2))), "APROVAT_AUTO", IF(F10=0,"SENSE_EQUIPS", IF(OR(AND(B10="EMP001", COUNTIF($B$2:B10,B10)>=3), AND(B10="EMP007", COUNTIF($B$2:B10,B10)>=2)), "LIMIT_SUPERAT", "REVISAR"))))) -> APROVAT_AUTO | I10: {=IF(H10="APROVAT_AUTO",IFERROR(INDEX(inventari!A:A,MATCH(1, (inventari!B:B=C10)*(inventari!G:G="Disponible")*(inventari!F:F="Si")*(COUNTIF($I$1:I9, inventari!A:A)=0), 0)), ""), "")} -> DD001
A11: =ROW()-1 -> 10 | B11: EMP010 | C11: Accessories | D11: 45702 | E11: =IF(D11="", "PENDENT_DATA", IF(SOL_LICITUDS_PRESTEC!G11<= SOL_LICITUDS_PRESTEC!H11, "OK", "ERROR_DATES")) -> OK | F11: =IF(B11="","", COUNTIFS(inventari!B:B,C11,inventari!F:F,"SI",inventari!G:G,"Disponible")-COUNTIFS($C$1:C10,C11,$H$1:H10,"APROVAT_AUTO")) -> 0 | G11: =IF(B11=""," ", COUNTIFS(inventari!H:H, B11, inventari!G:G, "En_Prestec") + COUNTIFS(SOL_LICITUDS_PRESTEC!D:D, B11, SOL_LICITUDS_PRESTEC!G:G, "<="&TODAY())) -> 2 | H11: =IF(B11="","", IF(E11="PENDENT_DATA","PENDENT_DATA", IF(AND(F11>0, E11="OK", NOT(AND(B11="EMP001", COUNTIF($B$2:B11,B11)>=3)), NOT(AND(B11="EMP007", COUNTIF($B$2:B11,B11)>=2))), "APROVAT_AUTO", IF(F11=0,"SENSE_EQUIPS", IF(OR(AND(B11="EMP001", COUNTIF($B$2:B11,B11)>=3), AND(B11="EMP007", COUNTIF($B$2:B11,B11)>=2)), "LIMIT_SUPERAT", "REVISAR"))))) -> SENSE_EQUIPS | I11: {=IF(H11="APROVAT_AUTO",IFERROR(INDEX(inventari!A:A,MATCH(1, (inventari!B:B=C11)*(inventari!G:G="Disponible")*(inventari!F:F="Si")*(COUNTIF($I$1:I10, inventari!A:A)=0), 0)), ""), "")}
A12: =ROW()-1 -> 11 | B12: EMP011 | C12: Tàblet | D12: 45703 | E12: =IF(D12="", "PENDENT_DATA", IF(SOL_LICITUDS_PRESTEC!G12<= SOL_LICITUDS_PRESTEC!H12, "OK", "ERROR_DATES")) -> OK | F12: =IF(B12="","", COUNTIFS(inventari!B:B,C12,inventari!F:F,"SI",inventari!G:G,"Disponible")-COUNTIFS($C$1:C11,C12,$H$1:H11,"APROVAT_AUTO")) -> 1 | G12: =IF(B12=""," ", COUNTIFS(inventari!H:H, B12, inventari!G:G, "En_Prestec") + COUNTIFS(SOL_LICITUDS_PRESTEC!D:D, B12, SOL_LICITUDS_PRESTEC!G:G, "<="&TODAY())) -> 2 | H12: =IF(B12="","", IF(E12="PENDENT_DATA","PENDENT_DATA", IF(AND(F12>0, E12="OK", NOT(AND(B12="EMP001", COUNTIF($B$2:B12,B12)>=3)), NOT(AND(B12="EMP007", COUNTIF($B$2:B12,B12)>=2))), "APROVAT_AUTO", IF(F12=0,"SENSE_EQUIPS", IF(OR(AND(B12="EMP001", COUNTIF($B$2:B12,B12)>=3), AND(B12="EMP007", COUNTIF($B$2:B12,B12)>=2)), "LIMIT_SUPERAT", "REVISAR"))))) -> APROVAT_AUTO | I12: {=IF(H12="APROVAT_AUTO",IFERROR(INDEX(inventari!A:A,MATCH(1, (inventari!B:B=C12)*(inventari!G:G="Disponible")*(inventari!F:F="Si")*(COUNTIF($I$1:I11, inventari!A:A)=0), 0)), ""), "")} -> TAB001
A13: =ROW()-1 -> 12 | B13: EMP012 | C13: Portàtil | D13: 45705 | E13: =IF(D13="", "PENDENT_DATA", IF(SOL_LICITUDS_PRESTEC!G13<= SOL_LICITUDS_PRESTEC!H13, "OK", "ERROR_DATES")) -> OK | F13: =IF(B13="","", COUNTIFS(inventari!B:B,C13,inventari!F:F,"SI",inventari!G:G,"Disponible")-COUNTIFS($C$1:C12,C13,$H$1:H12,"APROVAT_AUTO")) -> 1 | G13: =IF(B13=""," ", COUNTIFS(inventari!H:H, B13, inventari!G:G, "En_Prestec") + COUNTIFS(SOL_LICITUDS_PRESTEC!D:D, B13, SOL_LICITUDS_PRESTEC!G:G, "<="&TODAY())) -> 2 | H13: =IF(B13="","", IF(E13="PENDENT_DATA","PENDENT_DATA", IF(AND(F13>0, E13="OK", NOT(AND(B13="EMP001", COUNTIF($B$2:B13,B13)>=3)), NOT(AND(B13="EMP007", COUNTIF($B$2:B13,B13)>=2))), "APROVAT_AUTO", IF(F13=0,"SENSE_EQUIPS", IF(OR(AND(B13="EMP001", COUNTIF($B$2:B13,B13)>=3), AND(B13="EMP007", COUNTIF($B$2:B13,B13)>=2)), "LIMIT_SUPERAT", "REVISAR"))))) -> APROVAT_AUTO | I13: {=IF(H13="APROVAT_AUTO",IFERROR(INDEX(inventari!A:A,MATCH(1, (inventari!B:B=C13)*(inventari!G:G="Disponible")*(inventari!F:F="Si")*(COUNTIF($I$1:I12, inventari!A:A)=0), 0)), ""), "")} -> POR009
A14: =ROW()-1 -> 13 | B14: EMP013 | C14: Disc extern | D14: 45699 | E14: =IF(D14="", "PENDENT_DATA", IF(SOL_LICITUDS_PRESTEC!G14<= SOL_LICITUDS_PRESTEC!H14, "OK", "ERROR_DATES")) -> OK | F14: =IF(B14="","", COUNTIFS(inventari!B:B,C14,inventari!F:F,"SI",inventari!G:G,"Disponible")-COUNTIFS($C$1:C13,C14,$H$1:H13,"APROVAT_AUTO")) -> 1 | G14: =IF(B14=""," ", COUNTIFS(inventari!H:H, B14, inventari!G:G, "En_Prestec") + COUNTIFS(SOL_LICITUDS_PRESTEC!D:D, B14, SOL_LICITUDS_PRESTEC!G:G, "<="&TODAY())) -> 2 | H14: =IF(B14="","", IF(E14="PENDENT_DATA","PENDENT_DATA", IF(AND(F14>0, E14="OK", NOT(AND(B14="EMP001", COUNTIF($B$2:B14,B14)>=3)), NOT(AND(B14="EMP007", COUNTIF($B$2:B14,B14)>=2))), "APROVAT_AUTO", IF(F14=0,"SENSE_EQUIPS", IF(OR(AND(B14="EMP001", COUNTIF($B$2:B14,B14)>=3), AND(B14="EMP007", COUNTIF($B$2:B14,B14)>=2)), "LIMIT_SUPERAT", "REVISAR"))))) -> APROVAT_AUTO | I14: {=IF(H14="APROVAT_AUTO",IFERROR(INDEX(inventari!A:A,MATCH(1, (inventari!B:B=C14)*(inventari!G:G="Disponible")*(inventari!F:F="Si")*(COUNTIF($I$1:I13, inventari!A:A)=0), 0)), ""), "")} -> DD004
... A31: =ROW()-1 -> 30 | B31: EMP005 | C31: Projector | D31: 45706 | E31: =IF(D31="", "PENDENT_DATA", IF(SOL_LICITUDS_PRESTEC!G31<= SOL_LICITUDS_PRESTEC!H31, "OK", "ERROR_DATES")) -> OK | F31: =IF(B31="","", COUNTIFS(inventari!B:B,C31,inventari!F:F,"SI",inventari!G:G,"Disponible")-COUNTIFS($C$1:C30,C31,$H$1:H30,"APROVAT_AUTO")) -> 2 | G31: =IF(B31=""," ", COUNTIFS(inventari!H:H, B31, inventari!G:G, "En_Prestec") + COUNTIFS(SOL_LICITUDS_PRESTEC!D:D, B31, SOL_LICITUDS_PRESTEC!G:G, "<="&TODAY())) -> 3 | H31: =IF(B31="","", IF(E31="PENDENT_DATA","PENDENT_DATA", IF(AND(F31>0, E31="OK", NOT(AND(B31="EMP001", COUNTIF($B$2:B31,B31)>=3)), NOT(AND(B31="EMP007", COUNTIF($B$2:B31,B31)>=2))), "APROVAT_AUTO", IF(F31=0,"SENSE_EQUIPS", IF(OR(AND(B31="EMP001", COUNTIF($B$2:B31,B31)>=3), AND(B31="EMP007", COUNTIF($B$2:B31,B31)>=2)), "LIMIT_SUPERAT", "REVISAR"))))) -> APROVAT_AUTO | I31: {=IF(H31="APROVAT_AUTO",IFERROR(INDEX(inventari!A:A,MATCH(1, (inventari!B:B=C31)*(inventari!G:G="Disponible")*(inventari!F:F="Si")*(COUNTIF($I$1:I30, inventari!A:A)=0), 0)), ""), "")} -> PROJ001

Sheet RETORNADES
A1: Marca de temps | B1: Marca_temps | C1: Adreça_correu | D1: Codi_equip | E1: Estat_retornada | F1: Comentaris | G1: Confirmat | H1: Adreça electrònica
A2: 45698.688 | B2: 45698.688 | C2: maria.santos@electrotech.cat | D2: POR002 | E2: Perfecte | F2: Tot correcte sense problemes | G2: TRUE | H2: maria.santos@electrotech.cat
A3: 45698.719 | B3: 45698.719 | C3: carles.puig@electrotech.cat | D3: TAB002 | E3: Ratllades lleus | F3: Petita ratllada al marc | G3: TRUE | H3: carles.puig@electrotech.cat
A4: 45699.351 | B4: 45699.351 | C4: josep.ribas@electrotech.cat | D4: DD001 | E4: Perfecte | F4: Retorn estàndard | G4: TRUE | H4: josep.ribas@electrotech.cat
A5: 45699.405 | B5: 45699.405 | C5: laura.vidal@electrotech.cat | D5: MOB003 | E5: Perfecte | F5: Cap problema | G5: TRUE | H5: laura.vidal@electrotech.cat
A6: 45699.43 | B6: 45699.43 | C6: david.martin@electrotech.cat | D6: CAM002 | E6: Avaria menor | F6: L'estabilitzador fa soroll | G6: TRUE | H6: david.martin@electrotech.cat
A7: 45699.608 | B7: 45699.608 | C7: jordi.casals@electrotech.cat | D7: POR004 | E7: Perfecte | F7: Tot OK | G7: TRUE | H7: jordi.casals@electrotech.cat
A8: 45699.645 | B8: 45699.645 | C8: anna.mercader@electrotech.cat | D8: POR999 | E8: Perfecte | F8: Equip inexistent al sistema | G8: TRUE | H8: anna.mercader@electrotech.cat
A9: 45699.698 | B9: 45699.698 | C9: marta.ferrer@electrotech.cat | D9: TAB001 | E9: Ratllades lleus | F9: Ús normal | G9: TRUE | H9: marta.ferrer@electrotech.cat
A10: 45700.386 | B10: 45700.386 | C10: roger.pons@electrotech.cat | D10: DD002 | E10: Perfecte | F10: Sense incidències | G10: TRUE | H10: roger.pons@electrotech.cat
A11: 45700.444 | B11: 45700.444 | C11: sonia.camps@electrotech.cat | D11: ACC002 | E11: Avaria greu | F11: Teclat amb tecles que no funcionen | G11: TRUE | H11: sonia.camps@electrotech.cat
A12: 45700.495 | B12: 45700.495 | C12: pau.miro@electrotech.cat | D12: TAB008 | E12: Perfecte | F12: Tot correcte | G12: TRUE | H12: pau.miro@electrotech.cat
A13: 45700.601 | B13: 45700.601 | C13: clara.bosch@electrotech.cat | D13: POR010 | E13: Trencat/Inutilitzable | F13: Pantalla completament trencada | G13: TRUE | H13: clara.bosch@electrotech.cat
... A16: 45701.433 | B16: 45701.433 | C16: francesc.gil@electrotech.cat | D16: POR006 | E16: Ratllades lleus | F16: Algunes marques d'ús | G16: TRUE | H16: francesc.gil@electrotech.cat

Sheet RETORNADES_AUTO
A1: ID_equip | B1: Validacio_ID | C1: Validacio_prestec | D1: Estat_final | E1: Nou_estat_inventari | F1: Usuari_anterior | G1: Data_prestec_original
A2: {=RETORNADES!D2:D1000} -> POR002 | B2: =IF(A2="","",IF(COUNTIF(inventari!A:A,A2)>0,"ID_VALID","ID_NO_EXISTEIX")) -> ID_VALID | C2: =IF(A2="","",IF(B2="ID_VALID",IF(VLOOKUP(A2,inventari!A:Q,7, FALSE)="En_Prestec","PRESTEC_OK","NO_EN_PRESTEC"),"")) -> PRESTEC_OK | D2: =IF(A2="","",IF(AND(B2="ID_VALID",C2="PRESTEC_OK"),"RETORNADA_VALIDA","ERROR_VALIDACIO")) -> RETORNADA_VALIDA | E2: =IF(D2 = "RETORNADA_VALIDA", IFS( VLOOKUP(A2, RETORNADES!D:E, 2, FALSE) = "Perfecte", "Disponible", VLOOKUP(A2, RETORNADES!D:E, 2, FALSE) = "Ratllades lleus", "Disponible", VLOOKUP(A2, RETORNADES!D:E, 2, FALSE) = "Avaria menor", "Disponible", VLOOKUP(A2, RETORNADES!D:E, 2, FALSE) = "Avaria greu", "Manteniment", VLOOKUP(A2, RETORNADES!D:E, 2, FALSE) = "Trencat/Inutilitzable", "Manteniment", TRUE, "Pendent Revisió" ), "" ) -> Disponible | G2: =IF(B2="ID_VALID",VLOOKUP(A2,inventari!A:Q,9,FALSE),"") -> 45366
A3: TAB002 | B3: =IF(A3="","",IF(COUNTIF(inventari!A:A,A3)>0,"ID_VALID","ID_NO_EXISTEIX")) -> ID_VALID | C3: =IF(A3="","",IF(B3="ID_VALID",IF(VLOOKUP(A3,inventari!A:Q,7, FALSE)="En_Prestec","PRESTEC_OK","NO_EN_PRESTEC"),"")) -> PRESTEC_OK | D3: =IF(A3="","",IF(AND(B3="ID_VALID",C3="PRESTEC_OK"),"RETORNADA_VALIDA","ERROR_VALIDACIO")) -> RETORNADA_VALIDA | E3: =IF(D3 = "RETORNADA_VALIDA", IFS( VLOOKUP(A3, RETORNADES!D:E, 2, FALSE) = "Perfecte", "Disponible", VLOOKUP(A3, RETORNADES!D:E, 2, FALSE) = "Ratllades lleus", "Disponible", VLOOKUP(A3, RETORNADES!D:E, 2, FALSE) = "Avaria menor", "Disponible", VLOOKUP(A3, RETORNADES!D:E, 2, FALSE) = "Avaria greu", "Manteniment", VLOOKUP(A3, RETORNADES!D:E, 2, FALSE) = "Trencat/Inutilitzable", "Manteniment", TRUE, "Pendent Revisió" ), "" ) -> Disponible | F3: =IF(B3="ID_VALID",VLOOKUP(A3,inventari!A:Q,8,FALSE),"") -> EMP003 | G3: =IF(B3="ID_VALID",VLOOKUP(A3,inventari!A:Q,9,FALSE),"") -> 45371
A4: DD001 | B4: =IF(A4="","",IF(COUNTIF(inventari!A:A,A4)>0,"ID_VALID","ID_NO_EXISTEIX")) -> ID_VALID | C4: =IF(A4="","",IF(B4="ID_VALID",IF(VLOOKUP(A4,inventari!A:Q,7, FALSE)="En_Prestec","PRESTEC_OK","NO_EN_PRESTEC"),"")) -> NO_EN_PRESTEC | D4: =IF(A4="","",IF(AND(B4="ID_VALID",C4="PRESTEC_OK"),"RETORNADA_VALIDA","ERROR_VALIDACIO")) -> ERROR_VALIDACIO | E4: =IF(D4 = "RETORNADA_VALIDA", IFS( VLOOKUP(A4, RETORNADES!D:E, 2, FALSE) = "Perfecte", "Disponible", VLOOKUP(A4, RETORNADES!D:E, 2, FALSE) = "Ratllades lleus", "Disponible", VLOOKUP(A4, RETORNADES!D:E, 2, FALSE) = "Avaria menor", "Disponible", VLOOKUP(A4, RETORNADES!D:E, 2, FALSE) = "Avaria greu", "Manteniment", VLOOKUP(A4, RETORNADES!D:E, 2, FALSE) = "Trencat/Inutilitzable", "Manteniment", TRUE, "Pendent Revisió" ), "" ) | F4: =IF(B4="ID_VALID",VLOOKUP(A4,inventari!A:Q,8,FALSE),"") | G4: =IF(B4="ID_VALID",VLOOKUP(A4,inventari!A:Q,9,FALSE),"") -> Error
A5: MOB003 | B5: =IF(A5="","",IF(COUNTIF(inventari!A:A,A5)>0,"ID_VALID","ID_NO_EXISTEIX")) -> ID_VALID | C5: =IF(A5="","",IF(B5="ID_VALID",IF(VLOOKUP(A5,inventari!A:Q,7, FALSE)="En_Prestec","PRESTEC_OK","NO_EN_PRESTEC"),"")) -> PRESTEC_OK | D5: =IF(A5="","",IF(AND(B5="ID_VALID",C5="PRESTEC_OK"),"RETORNADA_VALIDA","ERROR_VALIDACIO")) -> RETORNADA_VALIDA | E5: =IF(D5 = "RETORNADA_VALIDA", IFS( VLOOKUP(A5, RETORNADES!D:E, 2, FALSE) = "Perfecte", "Disponible", VLOOKUP(A5, RETORNADES!D:E, 2, FALSE) = "Ratllades lleus", "Disponible", VLOOKUP(A5, RETORNADES!D:E, 2, FALSE) = "Avaria menor", "Disponible", VLOOKUP(A5, RETORNADES!D:E, 2, FALSE) = "Avaria greu", "Manteniment", VLOOKUP(A5, RETORNADES!D:E, 2, FALSE) = "Trencat/Inutilitzable", "Manteniment", TRUE, "Pendent Revisió" ), "" ) -> Disponible | F5: =IF(B5="ID_VALID",VLOOKUP(A5,inventari!A:Q,8,FALSE),"") -> EMP006 | G5: =IF(B5="ID_VALID",VLOOKUP(A5,inventari!A:Q,9,FALSE),"") -> 45367
A6: CAM002 | B6: =IF(A6="","",IF(COUNTIF(inventari!A:A,A6)>0,"ID_VALID","ID_NO_EXISTEIX")) -> ID_VALID | C6: =IF(A6="","",IF(B6="ID_VALID",IF(VLOOKUP(A6,inventari!A:Q,7, FALSE)="En_Prestec","PRESTEC_OK","NO_EN_PRESTEC"),"")) -> PRESTEC_OK | D6: =IF(A6="","",IF(AND(B6="ID_VALID",C6="PRESTEC_OK"),"RETORNADA_VALIDA","ERROR_VALIDACIO")) -> RETORNADA_VALIDA | E6: =IF(D6 = "RETORNADA_VALIDA", IFS( VLOOKUP(A6, RETORNADES!D:E, 2, FALSE) = "Perfecte", "Disponible", VLOOKUP(A6, RETORNADES!D:E, 2, FALSE) = "Ratllades lleus", "Disponible", VLOOKUP(A6, RETORNADES!D:E, 2, FALSE) = "Avaria menor", "Disponible", VLOOKUP(A6, RETORNADES!D:E, 2, FALSE) = "Avaria greu", "Manteniment", VLOOKUP(A6, RETORNADES!D:E, 2, FALSE) = "Trencat/Inutilitzable", "Manteniment", TRUE, "Pendent Revisió" ), "" ) -> Disponible | F6: =IF(B6="ID_VALID",VLOOKUP(A6,inventari!A:Q,8,FALSE),"") -> EMP005 | G6: =IF(B6="ID_VALID",VLOOKUP(A6,inventari!A:Q,9,FALSE),"") -> 45374
A7: POR004 | B7: =IF(A7="","",IF(COUNTIF(inventari!A:A,A7)>0,"ID_VALID","ID_NO_EXISTEIX")) -> ID_VALID | C7: =IF(A7="","",IF(B7="ID_VALID",IF(VLOOKUP(A7,inventari!A:Q,7, FALSE)="En_Prestec","PRESTEC_OK","NO_EN_PRESTEC"),"")) -> PRESTEC_OK | D7: =IF(A7="","",IF(AND(B7="ID_VALID",C7="PRESTEC_OK"),"RETORNADA_VALIDA","ERROR_VALIDACIO")) -> RETORNADA_VALIDA | E7: =IF(D7 = "RETORNADA_VALIDA", IFS( VLOOKUP(A7, RETORNADES!D:E, 2, FALSE) = "Perfecte", "Disponible", VLOOKUP(A7, RETORNADES!D:E, 2, FALSE) = "Ratllades lleus", "Disponible", VLOOKUP(A7, RETORNADES!D:E, 2, FALSE) = "Avaria menor", "Disponible", VLOOKUP(A7, RETORNADES!D:E, 2, FALSE) = "Avaria greu", "Manteniment", VLOOKUP(A7, RETORNADES!D:E, 2, FALSE) = "Trencat/Inutilitzable", "Manteniment", TRUE, "Pendent Revisió" ), "" ) -> Disponible | F7: =IF(B7="ID_VALID",VLOOKUP(A7,inventari!A:Q,8,FALSE),"") -> EMP007 | G7: =IF(B7="ID_VALID",VLOOKUP(A7,inventari!A:Q,9,FALSE),"") -> 45369
A8: POR999 | B8: =IF(A8="","",IF(COUNTIF(inventari!A:A,A8)>0,"ID_VALID","ID_NO_EXISTEIX")) -> ID_NO_EXISTEIX | C8: =IF(A8="","",IF(B8="ID_VALID",IF(VLOOKUP(A8,inventari!A:Q,7, FALSE)="En_Prestec","PRESTEC_OK","NO_EN_PRESTEC"),"")) | D8: =IF(A8="","",IF(AND(B8="ID_VALID",C8="PRESTEC_OK"),"RETORNADA_VALIDA","ERROR_VALIDACIO")) -> ERROR_VALIDACIO | E8: =IF(D8 = "RETORNADA_VALIDA", IFS( VLOOKUP(A8, RETORNADES!D:E, 2, FALSE) = "Perfecte", "Disponible", VLOOKUP(A8, RETORNADES!D:E, 2, FALSE) = "Ratllades lleus", "Disponible", VLOOKUP(A8, RETORNADES!D:E, 2, FALSE) = "Avaria menor", "Disponible", VLOOKUP(A8, RETORNADES!D:E, 2, FALSE) = "Avaria greu", "Manteniment", VLOOKUP(A8, RETORNADES!D:E, 2, FALSE) = "Trencat/Inutilitzable", "Manteniment", TRUE, "Pendent Revisió" ), "" ) | F8: =IF(B8="ID_VALID",VLOOKUP(A8,inventari!A:Q,8,FALSE),"") | G8: =IF(B8="ID_VALID",VLOOKUP(A8,inventari!A:Q,9,FALSE),"")
A9: TAB001 | B9: =IF(A9="","",IF(COUNTIF(inventari!A:A,A9)>0,"ID_VALID","ID_NO_EXISTEIX")) -> ID_VALID | C9: =IF(A9="","",IF(B9="ID_VALID",IF(VLOOKUP(A9,inventari!A:Q,7, FALSE)="En_Prestec","PRESTEC_OK","NO_EN_PRESTEC"),"")) -> NO_EN_PRESTEC | D9: =IF(A9="","",IF(AND(B9="ID_VALID",C9="PRESTEC_OK"),"RETORNADA_VALIDA","ERROR_VALIDACIO")) -> ERROR_VALIDACIO | E9: =IF(D9 = "RETORNADA_VALIDA", IFS( VLOOKUP(A9, RETORNADES!D:E, 2, FALSE) = "Perfecte", "Disponible", VLOOKUP(A9, RETORNADES!D:E, 2, FALSE) = "Ratllades lleus", "Disponible", VLOOKUP(A9, RETORNADES!D:E, 2, FALSE) = "Avaria menor", "Disponible", VLOOKUP(A9, RETORNADES!D:E, 2, FALSE) = "Avaria greu", "Manteniment", VLOOKUP(A9, RETORNADES!D:E, 2, FALSE) = "Trencat/Inutilitzable", "Manteniment", TRUE, "Pendent Revisió" ), "" ) | F9: =IF(B9="ID_VALID",VLOOKUP(A9,inventari!A:Q,8,FALSE),"") | G9: =IF(B9="ID_VALID",VLOOKUP(A9,inventari!A:Q,9,FALSE),"") -> Error
A10: DD002 | B10: =IF(A10="","",IF(COUNTIF(inventari!A:A,A10)>0,"ID_VALID","ID_NO_EXISTEIX")) -> ID_VALID | C10: =IF(A10="","",IF(B10="ID_VALID",IF(VLOOKUP(A10,inventari!A:Q,7, FALSE)="En_Prestec","PRESTEC_OK","NO_EN_PRESTEC"),"")) -> PRESTEC_OK | D10: =IF(A10="","",IF(AND(B10="ID_VALID",C10="PRESTEC_OK"),"RETORNADA_VALIDA","ERROR_VALIDACIO")) -> RETORNADA_VALIDA | E10: =IF(D10 = "RETORNADA_VALIDA", IFS( VLOOKUP(A10, RETORNADES!D:E, 2, FALSE) = "Perfecte", "Disponible", VLOOKUP(A10, RETORNADES!D:E, 2, FALSE) = "Ratllades lleus", "Disponible", VLOOKUP(A10, RETORNADES!D:E, 2, FALSE) = "Avaria menor", "Disponible", VLOOKUP(A10, RETORNADES!D:E, 2, FALSE) = "Avaria greu", "Manteniment", VLOOKUP(A10, RETORNADES!D:E, 2, FALSE) = "Trencat/Inutilitzable", "Manteniment", TRUE, "Pendent Revisió" ), "" ) -> Disponible | F10: =IF(B10="ID_VALID",VLOOKUP(A10,inventari!A:Q,8,FALSE),"") -> EMP009 | G10: =IF(B10="ID_VALID",VLOOKUP(A10,inventari!A:Q,9,FALSE),"") -> 45372
A11: ACC002 | B11: =IF(A11="","",IF(COUNTIF(inventari!A:A,A11)>0,"ID_VALID","ID_NO_EXISTEIX")) -> ID_VALID | C11: =IF(A11="","",IF(B11="ID_VALID",IF(VLOOKUP(A11,inventari!A:Q,7, FALSE)="En_Prestec","PRESTEC_OK","NO_EN_PRESTEC"),"")) -> PRESTEC_OK | D11: =IF(A11="","",IF(AND(B11="ID_VALID",C11="PRESTEC_OK"),"RETORNADA_VALIDA","ERROR_VALIDACIO")) -> RETORNADA_VALIDA | E11: =IF(D11 = "RETORNADA_VALIDA", IFS( VLOOKUP(A11, RETORNADES!D:E, 2, FALSE) = "Perfecte", "Disponible", VLOOKUP(A11, RETORNADES!D:E, 2, FALSE) = "Ratllades lleus", "Disponible", VLOOKUP(A11, RETORNADES!D:E, 2, FALSE) = "Avaria menor", "Disponible", VLOOKUP(A11, RETORNADES!D:E, 2, FALSE) = "Avaria greu", "Manteniment", VLOOKUP(A11, RETORNADES!D:E, 2, FALSE) = "Trencat/Inutilitzable", "Manteniment", TRUE, "Pendent Revisió" ), "" ) -> Manteniment | F11: =IF(B11="ID_VALID",VLOOKUP(A11,inventari!A:Q,8,FALSE),"") -> EMP010 | G11: =IF(B11="ID_VALID",VLOOKUP(A11,inventari!A:Q,9,FALSE),"") -> 45368
A12: TAB008 | B12: =IF(A12="","",IF(COUNTIF(inventari!A:A,A12)>0,"ID_VALID","ID_NO_EXISTEIX")) -> ID_VALID | C12: =IF(A12="","",IF(B12="ID_VALID",IF(VLOOKUP(A12,inventari!A:Q,7, FALSE)="En_Prestec","PRESTEC_OK","NO_EN_PRESTEC"),"")) -> PRESTEC_OK | D12: =IF(A12="","",IF(AND(B12="ID_VALID",C12="PRESTEC_OK"),"RETORNADA_VALIDA","ERROR_VALIDACIO")) -> RETORNADA_VALIDA | E12: =IF(D12 = "RETORNADA_VALIDA", IFS( VLOOKUP(A12, RETORNADES!D:E, 2, FALSE) = "Perfecte", "Disponible", VLOOKUP(A12, RETORNADES!D:E, 2, FALSE) = "Ratllades lleus", "Disponible", VLOOKUP(A12, RETORNADES!D:E, 2, FALSE) = "Avaria menor", "Disponible", VLOOKUP(A12, RETORNADES!D:E, 2, FALSE) = "Avaria greu", "Manteniment", VLOOKUP(A12, RETORNADES!D:E, 2, FALSE) = "Trencat/Inutilitzable", "Manteniment", TRUE, "Pendent Revisió" ), "" ) -> Disponible | F12: =IF(B12="ID_VALID",VLOOKUP(A12,inventari!A:Q,8,FALSE),"") -> EMP011 | G12: =IF(B12="ID_VALID",VLOOKUP(A12,inventari!A:Q,9,FALSE),"") -> 45361
A13: POR010 | B13: =IF(A13="","",IF(COUNTIF(inventari!A:A,A13)>0,"ID_VALID","ID_NO_EXISTEIX")) -> ID_VALID | C13: =IF(A13="","",IF(B13="ID_VALID",IF(VLOOKUP(A13,inventari!A:Q,7, FALSE)="En_Prestec","PRESTEC_OK","NO_EN_PRESTEC"),"")) -> PRESTEC_OK | D13: =IF(A13="","",IF(AND(B13="ID_VALID",C13="PRESTEC_OK"),"RETORNADA_VALIDA","ERROR_VALIDACIO")) -> RETORNADA_VALIDA | E13: =IF(D13 = "RETORNADA_VALIDA", IFS( VLOOKUP(A13, RETORNADES!D:E, 2, FALSE) = "Perfecte", "Disponible", VLOOKUP(A13, RETORNADES!D:E, 2, FALSE) = "Ratllades lleus", "Disponible", VLOOKUP(A13, RETORNADES!D:E, 2, FALSE) = "Avaria menor", "Disponible", VLOOKUP(A13, RETORNADES!D:E, 2, FALSE) = "Avaria greu", "Manteniment", VLOOKUP(A13, RETORNADES!D:E, 2, FALSE) = "Trencat/Inutilitzable", "Manteniment", TRUE, "Pendent Revisió" ), "" ) -> Manteniment | F13: =IF(B13="ID_VALID",VLOOKUP(A13,inventari!A:Q,8,FALSE),"") -> EMP015 | G13: =IF(B13="ID_VALID",VLOOKUP(A13,inventari!A:Q,9,FALSE),"") -> 45373
A14: ORD001 | B14: =IF(A14="","",IF(COUNTIF(inventari!A:A,A14)>0,"ID_VALID","ID_NO_EXISTEIX")) -> ID_VALID | C14: =IF(A14="","",IF(B14="ID_VALID",IF(VLOOKUP(A14,inventari!A:Q,7, FALSE)="En_Prestec","PRESTEC_OK","NO_EN_PRESTEC"),"")) -> NO_EN_PRESTEC | D14: =IF(A14="","",IF(AND(B14="ID_VALID",C14="PRESTEC_OK"),"RETORNADA_VALIDA","ERROR_VALIDACIO")) -> ERROR_VALIDACIO | E14: =IF(D14 = "RETORNADA_VALIDA", IFS( VLOOKUP(A14, RETORNADES!D:E, 2, FALSE) = "Perfecte", "Disponible", VLOOKUP(A14, RETORNADES!D:E, 2, FALSE) = "Ratllades lleus", "Disponible", VLOOKUP(A14, RETORNADES!D:E, 2, FALSE) = "Avaria menor", "Disponible", VLOOKUP(A14, RETORNADES!D:E, 2, FALSE) = "Avaria greu", "Manteniment", VLOOKUP(A14, RETORNADES!D:E, 2, FALSE) = "Trencat/Inutilitzable", "Manteniment", TRUE, "Pendent Revisió" ), "" ) | F14: =IF(B14="ID_VALID",VLOOKUP(A14,inventari!A:Q,8,FALSE),"") | G14: =IF(B14="ID_VALID",VLOOKUP(A14,inventari!A:Q,9,FALSE),"") -> Error
... A16: POR006 | B16: =IF(A16="","",IF(COUNTIF(inventari!A:A,A16)>0,"ID_VALID","ID_NO_EXISTEIX")) -> ID_VALID | C16: =IF(A16="","",IF(B16="ID_VALID",IF(VLOOKUP(A16,inventari!A:Q,7, FALSE)="En_Prestec","PRESTEC_OK","NO_EN_PRESTEC"),"")) -> PRESTEC_OK | D16: =IF(A16="","",IF(AND(B16="ID_VALID",C16="PRESTEC_OK"),"RETORNADA_VALIDA","ERROR_VALIDACIO")) -> RETORNADA_VALIDA | E16: =IF(D16 = "RETORNADA_VALIDA", IFS( VLOOKUP(A16, RETORNADES!D:E, 2, FALSE) = "Perfecte", "Disponible", VLOOKUP(A16, RETORNADES!D:E, 2, FALSE) = "Ratllades lleus", "Disponible", VLOOKUP(A16, RETORNADES!D:E, 2, FALSE) = "Avaria menor", "Disponible", VLOOKUP(A16, RETORNADES!D:E, 2, FALSE) = "Avaria greu", "Manteniment", VLOOKUP(A16, RETORNADES!D:E, 2, FALSE) = "Trencat/Inutilitzable", "Manteniment", TRUE, "Pendent Revisió" ), "" ) -> Disponible | F16: =IF(B16="ID_VALID",VLOOKUP(A16,inventari!A:Q,8,FALSE),"") -> EMP012 | G16: =IF(B16="ID_VALID",VLOOKUP(A16,inventari!A:Q,9,FALSE),"") -> 45350

Sheet REPARACIONS
A1: ID_Reparacio | B1: ID_Avaria | C1: Codi_equip | D1: Tipus_equip | E1: Problema_detectat | F1: Assignat_a | G1: Tipus_reparacio | H1: Data_inici | I1: Data_prevista_fi | J1: Estat_reparacio | K1: Cost_estimat | L1: Proveidor_extern | M1: Peces_necessaries | N1: Observacions_tecnic
A2: =IF(B2<>"", ROW()-1, "") -> 1 | B2: {=AVARIES_AUTO!A2:A1000} -> 1 | C2: {=AVARIES_AUTO!B2:B1000} -> POR007 | D2: =VLOOKUP(C2, inventari!A:Z, 2, FALSE) -> Portàtil | E2: =VLOOKUP(B2, AVARIES_AUTO!A:F, 6, FALSE) -> Pantalla trencada | F2: EXTERN_MARCA_FABRICANT | G2: =IFERROR(__xludf.DUMMYFUNCTION("( IF(C2<>"""", IFERROR( IF(REGEXMATCH(F2, ""INTERN""), ""INTERN"", IF(F2=""EXTERN_MARCA_FABRICANT"", ""GARANTIA"", IF(F2=""EXTERN_SERVEI_TECNIC"", ""PAGAMENT"", """" ) ) ), )))"),"GARANTIA") -> GARANTIA | H2: 45712.354 | I2: =IF(G2="GARANTIA", H2+10, IF(G2="intern", H2+3, IF(G2="PAGAMENT",H2+7,""))) -> 45722.354 | J2: FINALITZADA | K2: {=IF(ISBLANK(D2:D1000), "", IF(G2:G1000="GARANTIA", 0, IFERROR( VLOOKUP(D2:D1000, Costos_Reparacio!A:B, 2, FALSE), "COST_NO_TROBAT" ) ) )} -> 0 | L2: =IF(F2="", "No assignat", IF(OR(F2="INTERN_EMP005", F2="INTERN_EMP015", F2="INTERN_EMP030", F2="INTERN_EMP032"), "INTERN", IF(F2="EXTERN_SERVEI_TECNIC", "TALLER_LOCAL", IF(F2="EXTERN_MARCA_FABRICANT", "SERVEI_OFICIAL_MARCA", "Proveidor_extern" ) ) ) ) -> SERVEI_OFICIAL_MARCA
A3: =IF(B3<>"", ROW()-1, "") -> 2 | B3: 2 | C3: IMP002 | D3: =VLOOKUP(C3, inventari!A:Z, 2, FALSE) -> Impressora | E3: =VLOOKUP(B3, AVARIES_AUTO!A:F, 6, FALSE) -> Paper encallat (impressores) | F3: INTERN_EMP030 (Francesc Morera IT) | G3: =IFERROR(__xludf.DUMMYFUNCTION("( IF(C3<>"""", IFERROR( IF(REGEXMATCH(F3, ""INTERN""), ""INTERN"", IF(F3=""EXTERN_MARCA_FABRICANT"", ""GARANTIA"", IF(F3=""EXTERN_SERVEI_TECNIC"", ""PAGAMENT"", """" ) ) ), )))"),"INTERN") -> INTERN | H3: 45712.407 | I3: =IF(G3="GARANTIA", H3+10, IF(G3="intern", H3+3, IF(G3="PAGAMENT",H3+7,""))) -> 45715.406 | J3: FINALITZADA | K3: 75 | L3: =IF(F3="", "No assignat", IF(OR(F3="INTERN_EMP005", F3="INTERN_EMP015", F3="INTERN_EMP030", F3="INTERN_EMP032"), "INTERN", IF(F3="EXTERN_SERVEI_TECNIC", "TALLER_LOCAL", IF(F3="EXTERN_MARCA_FABRICANT", "SERVEI_OFICIAL_MARCA", "Proveidor_extern" ) ) ) ) -> Proveidor_extern
A4: =IF(B4<>"", ROW()-1, "") -> 3 | B4: 3 | C4: RAT002 | D4: =VLOOKUP(C4, inventari!A:Z, 2, FALSE) -> Ratolí | E4: =VLOOKUP(B4, AVARIES_AUTO!A:F, 6, FALSE) -> Touchpad/ratolí no funciona | F4: EXTERN_SERVEI_TECNIC | G4: =IFERROR(__xludf.DUMMYFUNCTION("( IF(C4<>"""", IFERROR( IF(REGEXMATCH(F4, ""INTERN""), ""INTERN"", IF(F4=""EXTERN_MARCA_FABRICANT"", ""GARANTIA"", IF(F4=""EXTERN_SERVEI_TECNIC"", ""PAGAMENT"", """" ) ) ), )))"),"PAGAMENT") -> PAGAMENT | H4: 45712.427 | I4: =IF(G4="GARANTIA", H4+10, IF(G4="intern", H4+3, IF(G4="PAGAMENT",H4+7,""))) -> 45719.427 | J4: FINALITZADA | K4: 15 | L4: =IF(F4="", "No assignat", IF(OR(F4="INTERN_EMP005", F4="INTERN_EMP015", F4="INTERN_EMP030", F4="INTERN_EMP032"), "INTERN", IF(F4="EXTERN_SERVEI_TECNIC", "TALLER_LOCAL", IF(F4="EXTERN_MARCA_FABRICANT", "SERVEI_OFICIAL_MARCA", "Proveidor_extern" ) ) ) ) -> TALLER_LOCAL
A5: =IF(B5<>"", ROW()-1, "") -> 4 | B5: 4 | C5: MON006 | D5: =VLOOKUP(C5, inventari!A:Z, 2, FALSE) -> Monitor | E5: =VLOOKUP(B5, AVARIES_AUTO!A:F, 6, FALSE) -> Pantalla no funciona | F5: EXTERN_SERVEI_TECNIC | G5: =IFERROR(__xludf.DUMMYFUNCTION("( IF(C5<>"""", IFERROR( IF(REGEXMATCH(F5, ""INTERN""), ""INTERN"", IF(F5=""EXTERN_MARCA_FABRICANT"", ""GARANTIA"", IF(F5=""EXTERN_SERVEI_TECNIC"", ""PAGAMENT"", """" ) ) ), )))"),"PAGAMENT") -> PAGAMENT | H5: 45712.473 | I5: =IF(G5="GARANTIA", H5+10, IF(G5="intern", H5+3, IF(G5="PAGAMENT",H5+7,""))) -> 45719.473 | J5: FINALITZADA | K5: 85 | L5: =IF(F5="", "No assignat", IF(OR(F5="INTERN_EMP005", F5="INTERN_EMP015", F5="INTERN_EMP030", F5="INTERN_EMP032"), "INTERN", IF(F5="EXTERN_SERVEI_TECNIC", "TALLER_LOCAL", IF(F5="EXTERN_MARCA_FABRICANT", "SERVEI_OFICIAL_MARCA", "Proveidor_extern" ) ) ) ) -> TALLER_LOCAL
A6: =IF(B6<>"", ROW()-1, "") -> 5 | B6: 5 | C6: ORD002 | D6: =VLOOKUP(C6, inventari!A:Z, 2, FALSE) -> Ordinador | E6: =VLOOKUP(B6, AVARIES_AUTO!A:F, 6, FALSE) -> No s'encén | F6: EXTERN_SERVEI_TECNIC | G6: =IFERROR(__xludf.DUMMYFUNCTION("( IF(C6<>"""", IFERROR( IF(REGEXMATCH(F6, ""INTERN""), ""INTERN"", IF(F6=""EXTERN_MARCA_FABRICANT"", ""GARANTIA"", IF(F6=""EXTERN_SERVEI_TECNIC"", ""PAGAMENT"", """" ) ) ), )))"),"PAGAMENT") -> PAGAMENT | H6: 45712.525 | I6: =IF(G6="GARANTIA", H6+10, IF(G6="intern", H6+3, IF(G6="PAGAMENT",H6+7,""))) -> 45719.524 | J6: FINALITZADA | K6: 120 | L6: =IF(F6="", "No assignat", IF(OR(F6="INTERN_EMP005", F6="INTERN_EMP015", F6="INTERN_EMP030", F6="INTERN_EMP032"), "INTERN", IF(F6="EXTERN_SERVEI_TECNIC", "TALLER_LOCAL", IF(F6="EXTERN_MARCA_FABRICANT", "SERVEI_OFICIAL_MARCA", "Proveidor_extern" ) ) ) ) -> TALLER_LOCAL
A7: =IF(B7<>"", ROW()-1, "") -> 6 | B7: 6 | C7: TAB006 | D7: =VLOOKUP(C7, inventari!A:Z, 2, FALSE) -> Tàblet | E7: =VLOOKUP(B7, AVARIES_AUTO!A:F, 6, FALSE) -> Kickstand trencat (tàblets) | F7: EXTERN_MARCA_FABRICANT | G7: =IFERROR(__xludf.DUMMYFUNCTION("( IF(C7<>"""", IFERROR( IF(REGEXMATCH(F7, ""INTERN""), ""INTERN"", IF(F7=""EXTERN_MARCA_FABRICANT"", ""GARANTIA"", IF(F7=""EXTERN_SERVEI_TECNIC"", ""PAGAMENT"", """" ) ) ), )))"),"GARANTIA") -> GARANTIA | H7: 45712.599 | I7: =IF(G7="GARANTIA", H7+10, IF(G7="intern", H7+3, IF(G7="PAGAMENT",H7+7,""))) -> 45722.599 | J7: FINALITZADA | K7: 0 | L7: =IF(F7="", "No assignat", IF(OR(F7="INTERN_EMP005", F7="INTERN_EMP015", F7="INTERN_EMP030", F7="INTERN_EMP032"), "INTERN", IF(F7="EXTERN_SERVEI_TECNIC", "TALLER_LOCAL", IF(F7="EXTERN_MARCA_FABRICANT", "SERVEI_OFICIAL_MARCA", "Proveidor_extern" ) ) ) ) -> SERVEI_OFICIAL_MARCA
A8: =IF(B8<>"", ROW()-1, "") -> 7 | B8: 7 | C8: MOB001 | D8: =VLOOKUP(C8, inventari!A:Z, 2, FALSE) -> Mòbil | E8: =VLOOKUP(B8, AVARIES_AUTO!A:F, 6, FALSE) -> Bateria no carrega | F8: EXTERN_MARCA_FABRICANT | G8: =IFERROR(__xludf.DUMMYFUNCTION("( IF(C8<>"""", IFERROR( IF(REGEXMATCH(F8, ""INTERN""), ""INTERN"", IF(F8=""EXTERN_MARCA_FABRICANT"", ""GARANTIA"", IF(F8=""EXTERN_SERVEI_TECNIC"", ""PAGAMENT"", """" ) ) ), )))"),"GARANTIA") -> GARANTIA | H8: 45712.632 | I8: =IF(G8="GARANTIA", H8+10, IF(G8="intern", H8+3, IF(G8="PAGAMENT",H8+7,""))) -> 45722.632 | J8: FINALITZADA | K8: 0 | L8: =IF(F8="", "No assignat", IF(OR(F8="INTERN_EMP005", F8="INTERN_EMP015", F8="INTERN_EMP030", F8="INTERN_EMP032"), "INTERN", IF(F8="EXTERN_SERVEI_TECNIC", "TALLER_LOCAL", IF(F8="EXTERN_MARCA_FABRICANT", "SERVEI_OFICIAL_MARCA", "Proveidor_extern" ) ) ) ) -> SERVEI_OFICIAL_MARCA
A9: =IF(B9<>"", ROW()-1, "") -> 8 | B9: 8 | C9: CAM004 | D9: =VLOOKUP(C9, inventari!A:Z, 2, FALSE) -> Càmera | E9: =VLOOKUP(B9, AVARIES_AUTO!A:F, 6, FALSE) -> Càmera no enfoca | F9: EXTERN_SERVEI_TECNIC | G9: =IFERROR(__xludf.DUMMYFUNCTION("( IF(C9<>"""", IFERROR( IF(REGEXMATCH(F9, ""INTERN""), ""INTERN"", IF(F9=""EXTERN_MARCA_FABRICANT"", ""GARANTIA"", IF(F9=""EXTERN_SERVEI_TECNIC"", ""PAGAMENT"", """" ) ) ), )))"),"PAGAMENT") -> PAGAMENT | H9: 45712.698 | I9: =IF(G9="GARANTIA", H9+10, IF(G9="intern", H9+3, IF(G9="PAGAMENT",H9+7,""))) -> 45719.698 | J9: FINALITZADA | K9: 180 | L9: =IF(F9="", "No assignat", IF(OR(F9="INTERN_EMP005", F9="INTERN_EMP015", F9="INTERN_EMP030", F9="INTERN_EMP032"), "INTERN", IF(F9="EXTERN_SERVEI_TECNIC", "TALLER_LOCAL", IF(F9="EXTERN_MARCA_FABRICANT", "SERVEI_OFICIAL_MARCA", "Proveidor_extern" ) ) ) ) -> TALLER_LOCAL
A10: =IF(B10<>"", ROW()-1, "") -> 9 | B10: 9 | C10: PROJ003 | D10: =VLOOKUP(C10, inventari!A:Z, 2, FALSE) -> Projector | E10: =VLOOKUP(B10, AVARIES_AUTO!A:F, 6, FALSE) -> Projector sense imatge | F10: EXTERN_SERVEI_TECNIC | G10: =IFERROR(__xludf.DUMMYFUNCTION("( IF(C10<>"""", IFERROR( IF(REGEXMATCH(F10, ""INTERN""), ""INTERN"", IF(F10=""EXTERN_MARCA_FABRICANT"", ""GARANTIA"", IF(F10=""EXTERN_SERVEI_TECNIC"", ""PAGAMENT"", """" ) ) ), )))"),"PAGAMENT") -> PAGAMENT | H10: 45712.729 | I10: =IF(G10="GARANTIA", H10+10, IF(G10="intern", H10+3, IF(G10="PAGAMENT",H10+7,""))) -> 45719.729 | J10: FINALITZADA | K10: 200 | L10: =IF(F10="", "No assignat", IF(OR(F10="INTERN_EMP005", F10="INTERN_EMP015", F10="INTERN_EMP030", F10="INTERN_EMP032"), "INTERN", IF(F10="EXTERN_SERVEI_TECNIC", "TALLER_LOCAL", IF(F10="EXTERN_MARCA_FABRICANT", "SERVEI_OFICIAL_MARCA", "Proveidor_extern" ) ) ) ) -> TALLER_LOCAL
A11: =IF(B11<>"", ROW()-1, "") -> 10 | B11: 10 | C11: XXX999 | D11: =VLOOKUP(C11, inventari!A:Z, 2, FALSE) -> #N/A | E11: =VLOOKUP(B11, AVARIES_AUTO!A:F, 6, FALSE) -> Software corromput | G11: =IFERROR(__xludf.DUMMYFUNCTION("( IF(C11<>"""", IFERROR( IF(REGEXMATCH(F11, ""INTERN""), ""INTERN"", IF(F11=""EXTERN_MARCA_FABRICANT"", ""GARANTIA"", IF(F11=""EXTERN_SERVEI_TECNIC"", ""PAGAMENT"", """" ) ) ), )))"),"") | H11: 45713.386 | I11: =IF(G11="GARANTIA", H11+10, IF(G11="intern", H11+3, IF(G11="PAGAMENT",H11+7,""))) | J11: FINALITZADA | K11: COST_NO_TROBAT | L11: =IF(F11="", "No assignat", IF(OR(F11="INTERN_EMP005", F11="INTERN_EMP015", F11="INTERN_EMP030", F11="INTERN_EMP032"), "INTERN", IF(F11="EXTERN_SERVEI_TECNIC", "TALLER_LOCAL", IF(F11="EXTERN_MARCA_FABRICANT", "SERVEI_OFICIAL_MARCA", "Proveidor_extern" ) ) ) ) -> No assignat
A12: =IF(B12<>"", ROW()-1, "") -> 11 | B12: 11 | C12: POR003 | D12: =VLOOKUP(C12, inventari!A:Z, 2, FALSE) -> Portàtil | E12: =VLOOKUP(B12, AVARIES_AUTO!A:F, 6, FALSE) -> Lentitud extrema | F12: EXTERN_SERVEI_TECNIC | G12: =IFERROR(__xludf.DUMMYFUNCTION("( IF(C12<>"""", IFERROR( IF(REGEXMATCH(F12, ""INTERN""), ""INTERN"", IF(F12=""EXTERN_MARCA_FABRICANT"", ""GARANTIA"", IF(F12=""EXTERN_SERVEI_TECNIC"", ""PAGAMENT"", """" ) ) ), )))"),"PAGAMENT") -> PAGAMENT | H12: 45713.437 | I12: =IF(G12="GARANTIA", H12+10, IF(G12="intern", H12+3, IF(G12="PAGAMENT",H12+7,""))) -> 45720.437 | J12: FINALITZADA | K12: 150 | L12: =IF(F12="", "No assignat", IF(OR(F12="INTERN_EMP005", F12="INTERN_EMP015", F12="INTERN_EMP030", F12="INTERN_EMP032"), "INTERN", IF(F12="EXTERN_SERVEI_TECNIC", "TALLER_LOCAL", IF(F12="EXTERN_MARCA_FABRICANT", "SERVEI_OFICIAL_MARCA", "Proveidor_extern" ) ) ) ) -> TALLER_LOCAL
A13: =IF(B13<>"", ROW()-1, "") -> 12 | B13: 12 | C13: DD003 | D13: =VLOOKUP(C13, inventari!A:Z, 2, FALSE) -> Disc extern | E13: =VLOOKUP(B13, AVARIES_AUTO!A:F, 6, FALSE) -> Altres | F13: INTERN_EMP032 (Eduard Civit de manteniment) | G13: =IFERROR(__xludf.DUMMYFUNCTION("( IF(C13<>"""", IFERROR( IF(REGEXMATCH(F13, ""INTERN""), ""INTERN"", IF(F13=""EXTERN_MARCA_FABRICANT"", ""GARANTIA"", IF(F13=""EXTERN_SERVEI_TECNIC"", ""PAGAMENT"", """" ) ) ), )))"),"INTERN") -> INTERN | H13: 45713.49 | I13: =IF(G13="GARANTIA", H13+10, IF(G13="intern", H13+3, IF(G13="PAGAMENT",H13+7,""))) -> 45716.49 | J13: FINALITZADA | K13: 60 | L13: =IF(F13="", "No assignat", IF(OR(F13="INTERN_EMP005", F13="INTERN_EMP015", F13="INTERN_EMP030", F13="INTERN_EMP032"), "INTERN", IF(F13="EXTERN_SERVEI_TECNIC", "TALLER_LOCAL", IF(F13="EXTERN_MARCA_FABRICANT", "SERVEI_OFICIAL_MARCA", "Proveidor_extern" ) ) ) ) -> Proveidor_extern
A14: =IF(B14<>"", ROW()-1, "") -> 13 | B14: 13 | C14: TEC002 | D14: =VLOOKUP(C14, inventari!A:Z, 2, FALSE) -> Teclat | E14: =VLOOKUP(B14, AVARIES_AUTO!A:F, 6, FALSE) -> Teclat no funciona | F14: INTERN_EMP005 (David Martín IT) | G14: =IFERROR(__xludf.DUMMYFUNCTION("( IF(C14<>"""", IFERROR( IF(REGEXMATCH(F14, ""INTERN""), ""INTERN"", IF(F14=""EXTERN_MARCA_FABRICANT"", ""GARANTIA"", IF(F14=""EXTERN_SERVEI_TECNIC"", ""PAGAMENT"", """" ) ) ), )))"),"INTERN") -> INTERN | H14: 45713.599 | I14: =IF(G14="GARANTIA", H14+10, IF(G14="intern", H14+3, IF(G14="PAGAMENT",H14+7,""))) -> 45716.599 | J14: FINALITZADA | K14: 25 | L14: =IF(F14="", "No assignat", IF(OR(F14="INTERN_EMP005", F14="INTERN_EMP015", F14="INTERN_EMP030", F14="INTERN_EMP032"), "INTERN", IF(F14="EXTERN_SERVEI_TECNIC", "TALLER_LOCAL", IF(F14="EXTERN_MARCA_FABRICANT", "SERVEI_OFICIAL_MARCA", "Proveidor_extern" ) ) ) ) -> Proveidor_extern

Sheet Dashboard
A2: INVENTARI GENERAL | B2: Total equips | C2: =COUNTA(inventari!A:A) - 1 -> 92 | L2: Equips en préstec | Q2: Persona | R2: Ext
B3: Disponibles | C3: =COUNTIF(inventari!G:G, "Disponible") -> 43
B4: En préstec | C4: =COUNTIF(inventari!G:G, "En_Prestec") -> 15
B5: Avariats | C5: =COUNTIF(inventari!G:G, "Avariat") -> 7
B6: En manteniment | C6: =COUNTIF(inventari!G:G, "Manteniment") -> 27
B7: Retirats | C7: =COUNTIF(inventari!G:G, "Retirats") -> 0
B8: Equip prestables | C8: =COUNTIF(inventari!F:F, "Si") -> 58
B9: Equip fixos operatius | C9: =COUNTIF(inventari!F:F, "No") -> 34
A11: PRÉSTECS | B11: Préstec actius | C11: =COUNTIF(inventari!G:G, "En_Prestec") -> 15
B12: Sol·licituds pendents | C12: =COUNTIF(APROVACIONS_AUTO!H:H, "SENSE_EQUIPS") -> 16
B13: Aprovacions automàtiques | C13: =COUNTIF(APROVACIONS_AUTO!H:H, "APROVAT_AUTO") -> 14
B14: Préstecs endarrerits
B15: Dies mitjans préstecs
B16: Percentatge disponibilitat
A18: AVARIES | B18: Averies notificades | C18: =COUNTA(AVARIES_AUTO!A2:A1000) -> 13
B19: Averies pendent revisar | C19: =COUNTIF(AVARIES_AUTO!K:K, "PENDENT_REVISAR") -> 8
B20: Averies en garantia | C20: =COUNTIF(AVARIES_AUTO!K:K, "PENDENT_GARANTIA") -> 4
B21: Averies gravetat alta | C21: =COUNTIF(AVARIES_AUTO!G:G, "5") -> 3
B22: Percentatge sota garantia | C22: =IFERROR(COUNTIF(AVARIES_AUTO!K:K,"PENDENT_GARANTIA")/(COUNTA(AVARIES_AUTO!C:C, "ID_VALID")),"") -> 0.26666667
A24: REPARACIONS | B24: Reparacions actives | C24: =COUNTIF(REPARACIONS!J:J,"EN_REPARACIO") -> 0
B25: Finalitzades aquest mes | C25: =COUNTIF(REPARACIONS!I:I, "12/2025") -> 0
B26: Cost total reparacions | C26: =SUM(REPARACIONS!K:K) -> 910
B27: Reparacions garantia | C27: =COUNTIF(REPARACIONS!G:G, "GARANTIA") -> 3
B28: Equips irreparables | C28: =COUNTIF(REPARACIONS!J:J, "IRREPARABLE") -> 0
A30: FINALITZAR PREPARACIONS | B30: Reparacions finalitzades | C30: =COUNTIF(REPARACIONS!J:J, "FINALITZADA") -> 13
B31: Equips per reactivar
B32: Equips per retirar
B33: Costos per facturar
B34: Actualitzacions pendents
A37: Tipus | B37: Disponibles | C37: En_Prestec
A38: Portátil

Sheet AVARIES
A1: Marca de temps | B1: Adreça electrònica | C1: Codi de l'equip avariat | D1: Usuari que reporta | E1: Tipus de problema | F1: Descripció detallada del problema | G1: Quan vas detectar el problema? | H1: L'equip estava en préstec? | I1: Gravetat del problema | J1: És urgent la reparació?
A2: 45712.354 | B2: maria.santos@electrotech.cat | C2: POR007 | D2: EMP001 - Maria Santos (Comercial) | E2: Pantalla trencada | F2: La pantalla del portàtil s'ha trencat completament després d'una caiguda. No es veu res | G2: Ara mateix | H2: Sí jo el tinia en préstec | I2: 5 | J2: Molt urgent (atura treball)
A3: 45712.407 | B3: ramon.serra@electrotech.cat | C3: IMP002 | D3: EMP019 - Ramon Serra (Manteniment) | E3: Paper encallat (impressores) | F3: La impressora de comercial té paper encallat constant. Ja he provat treure'l però torna a passar | G3: Aquesta setmana | H3: No estava a l'oficina | I3: 3 | J3: Normal (es pot esperar)
A4: 45712.427 | B4: josep.ribas@electrotech.cat | C4: RAT002 | D4: EMP002 - Josep Ribas (Administració) | E4: Touchpad/ratolí no funciona | F4: El botó dret del ratolí del meu despatx no funciona. És molt molest per treballar | G4: Fa 2-3 dies | H4: No estava a l'oficina | I4: 3 | J4: Urgent (afecta productivitat)
A5: 45712.473 | B5: carles.puig@electrotech.cat | C5: MON006 | D5: EMP003 - Carles Puig (Tècnic) | E5: Pantalla no funciona | F5: El monitor secundari d'enginyeria té píxels morts al centre. Es veu una línia negra | G5: Ahir | H5: No estava a l'oficina | I5: 2 | J5: Normal (es pot esperar)
A6: 45712.525 | B6: montse.valls@electrotech.cat | C6: ORD002 | D6: EMP021 - Montse Valls (Neteja) | E6: No s'encén | F6: L'ordinador del despatx 02 no s'encén quan premo el botó. Les llums no fan res | G6: Avui al matí | H6: No ho sé | I6: 5 | J6: Molt urgent (atura treball)
A7: 45712.599 | B7: david.martin@electrotech.cat | C7: TAB006 | D7: EMP005 - David Martín (IT) | E7: Kickstand trencat (tàblets) | F7: El suport de la Surface Pro està trencat. No es manté dreta per treballar | G7: Fa 2-3 dies | H7: No estava a l'oficina | I7: 3 | J7: Normal (es pot esperar)
A8: 45712.632 | B8: laura.vidal@electrotech.cat | C8: MOB001 | D8: EMP006 - Laura Vidal (Marketing) | E8: Bateria no carrega | F8: L'iPhone del magatzem té la bateria gonflada i no carrega. Sembla perillós | G8: Aquesta setmana | H8: No estava a l'oficina | I8: 4 | J8: Urgent (afecta productivitat)
A9: 45712.698 | B9: eva.torres@electrotech.cat | C9: CAM004 | D9: EMP016 - Eva Torres (Marketing) | E9: Càmera no enfoca | F9: La DJI Pocket no enfoca bé. L'estabilitzador fa sorolls estranys | G9: Ahir | H9: No estava a l'oficina | I9: 4 | J9: Urgent (afecta productivitat)
A10: 45712.729 | B10: carmen.lopez@electrotech.cat | C10: PROJ003 | D10: EMP023 - Carmen López (Recepció) | E10: Projector sense imatge | F10: El projector de la sala A no dona imatge. S'encén però pantalla negra | G10: Ara mateix | H10: No estava a l'oficina | I10: 4 | J10: Urgent (afecta productivitat)
A11: 45713.386 | B11: pau.miro@electrotech.cat | C11: XXX999 | D11: EMP011 - Pau Miró (Marketing) | E11: Software corromput | F11: El meu portàtil no arrenca. Codi inexistent al sistema | G11: Avui al matí | H11: Sí jo el tinia en préstec | I11: 5 | J11: Molt urgent (atura treball)
A12: 45713.437 | B12: jordi.casals@electrotech.cat | C12: POR003 | D12: EMP007 - Jordi Casals (Tècnic) | E12: Lentitud extrema | F12: El portàtil va molt lent. Triga 10 minuts a arrencar | G12: Aquesta setmana | H12: No estava a l'oficina | I12: 3 | J12: Normal (es pot esperar)
A13: 45713.49 | B13: clara.bosch@electrotech.cat | C13: DD003 | D13: EMP012 - Clara Bosch (Comercial) | E13: Altres | F13: El disc extern fa sorolls estranys quan es connecta | G13: Fa 2-3 dies | H13: No ho sé | I13: 3 | J13: Normal (es pot esperar)
A14: 45713.599 | B14: albert.roca@electrotech.cat | C14: TEC002 | D14: EMP013 - Albert Roca (Tècnic) | E14: Teclat no funciona | F14: La tecla Enter del teclat va intermitent. A vegades funciona i a vegades no | G14: Ahir | H14: No estava a l'oficina | I14: 2 | J14: Baixa prioritat

Sheet AVARIES_AUTO
A1: ID_Avaria | B1: Codi_equip | C1: Validacio_equip | D1: Estat_actual_equip | E1: Usuari_reporta | F1: Tipus_problema | G1: Gravetat | H1: Urgencia | I1: Data_notificacio | J1: Garantia_vigent | K1: Estat_avaria
A2: =ROW() - 1 -> 1 | B2: {=AVARIES!C2:C1000} -> POR007 | C2: =IF(ISNA(VLOOKUP(B2, inventari!A:A, 1, FALSE)), "EQUIP_NO_EXISTEIX", "ID_VALID") -> ID_VALID | D2: =IF(C2="ID_VALID", VLOOKUP(B2, inventari!A:E, 5, FALSE), "N/A") -> Comercial_04 | E2: {=AVARIES!D2:D1000} -> EMP001 - Maria Santos (Comercial) | F2: {=AVARIES!E2:E1000} -> Pantalla trencada | G2: {=AVARIES!I2:I1000} -> 5 | H2: {=AVARIES!J2:J1000} -> Molt urgent (atura treball) | I2: {=AVARIES!A2:A1000} -> 45712.354 | J2: {=IF(ISBLANK(B2:B1000),"",IF(C2:C1000="ID_VALID",IFERROR(TRIM(VLOOKUP(TRIM(B2:B1000),inventari!A:N,14,FALSE)),"ERROR_CERCAT"),"NO_APLICA"))} -> VIGENT | K2: =IF(C2="EQUIP_NO_EXISTEIX", "ERROR_EQUIP", IF(J2="VIGENT", "PENDENT_GARANTIA", "PENDENT_REVISAR")) -> PENDENT_GARANTIA
A3: =ROW() - 1 -> 2 | B3: IMP002 | C3: =IF(ISNA(VLOOKUP(B3, inventari!A:A, 1, FALSE)), "EQUIP_NO_EXISTEIX", "ID_VALID") -> ID_VALID | D3: =IF(C3="ID_VALID", VLOOKUP(B3, inventari!A:E, 5, FALSE), "N/A") -> ENGINYERIA_02 | E3: EMP019 - Ramon Serra (Manteniment) | F3: Paper encallat (impressores) | G3: 3 | H3: Normal (es pot esperar) | I3: 45712.407 | J3: CADUCADA | K3: =IF(C3="EQUIP_NO_EXISTEIX", "ERROR_EQUIP", IF(J3="VIGENT", "PENDENT_GARANTIA", "PENDENT_REVISAR")) -> PENDENT_REVISAR
A4: =ROW() - 1 -> 3 | B4: RAT002 | C4: =IF(ISNA(VLOOKUP(B4, inventari!A:A, 1, FALSE)), "EQUIP_NO_EXISTEIX", "ID_VALID") -> ID_VALID | D4: =IF(C4="ID_VALID", VLOOKUP(B4, inventari!A:E, 5, FALSE), "N/A") -> DESPATX_02 | E4: EMP002 - Josep Ribas (Administració) | F4: Touchpad/ratolí no funciona | G4: 3 | H4: Urgent (afecta productivitat) | I4: 45712.427 | J4: CADUCADA | K4: =IF(C4="EQUIP_NO_EXISTEIX", "ERROR_EQUIP", IF(J4="VIGENT", "PENDENT_GARANTIA", "PENDENT_REVISAR")) -> PENDENT_REVISAR
A5: =ROW() - 1 -> 4 | B5: MON006 | C5: =IF(ISNA(VLOOKUP(B5, inventari!A:A, 1, FALSE)), "EQUIP_NO_EXISTEIX", "ID_VALID") -> ID_VALID | D5: =IF(C5="ID_VALID", VLOOKUP(B5, inventari!A:E, 5, FALSE), "N/A") -> ENGINYERIA_02 | E5: EMP003 - Carles Puig (Tècnic) | F5: Pantalla no funciona | G5: 2 | H5: Normal (es pot esperar) | I5: 45712.473 | J5: CADUCADA | K5: =IF(C5="EQUIP_NO_EXISTEIX", "ERROR_EQUIP", IF(J5="VIGENT", "PENDENT_GARANTIA", "PENDENT_REVISAR")) -> PENDENT_REVISAR
A6: =ROW() - 1 -> 5 | B6: ORD002 | C6: =IF(ISNA(VLOOKUP(B6, inventari!A:A, 1, FALSE)), "EQUIP_NO_EXISTEIX", "ID_VALID") -> ID_VALID | D6: =IF(C6="ID_VALID", VLOOKUP(B6, inventari!A:E, 5, FALSE), "N/A") -> DESPATX_02 | E6: EMP021 - Montse Valls (Neteja) | F6: No s'encén | G6: 5 | H6: Molt urgent (atura treball) | I6: 45712.525 | J6: CADUCADA | K6: =IF(C6="EQUIP_NO_EXISTEIX", "ERROR_EQUIP", IF(J6="VIGENT", "PENDENT_GARANTIA", "PENDENT_REVISAR")) -> PENDENT_REVISAR
A7: =ROW() - 1 -> 6 | B7: TAB006 | C7: =IF(ISNA(VLOOKUP(B7, inventari!A:A, 1, FALSE)), "EQUIP_NO_EXISTEIX", "ID_VALID") -> ID_VALID | D7: =IF(C7="ID_VALID", VLOOKUP(B7, inventari!A:E, 5, FALSE), "N/A") -> MAGATZEM | E7: EMP005 - David Martín (IT) | F7: Kickstand trencat (tàblets) | G7: 3 | H7: Normal (es pot esperar) | I7: 45712.599 | J7: VIGENT | K7: =IF(C7="EQUIP_NO_EXISTEIX", "ERROR_EQUIP", IF(J7="VIGENT", "PENDENT_GARANTIA", "PENDENT_REVISAR")) -> PENDENT_GARANTIA
A8: =ROW() - 1 -> 7 | B8: MOB001 | C8: =IF(ISNA(VLOOKUP(B8, inventari!A:A, 1, FALSE)), "EQUIP_NO_EXISTEIX", "ID_VALID") -> ID_VALID | D8: =IF(C8="ID_VALID", VLOOKUP(B8, inventari!A:E, 5, FALSE), "N/A") -> MAGATZEM | E8: EMP006 - Laura Vidal (Marketing) | F8: Bateria no carrega | G8: 4 | H8: Urgent (afecta productivitat) | I8: 45712.632 | J8: VIGENT | K8: =IF(C8="EQUIP_NO_EXISTEIX", "ERROR_EQUIP", IF(J8="VIGENT", "PENDENT_GARANTIA", "PENDENT_REVISAR")) -> PENDENT_GARANTIA
A9: =ROW() - 1 -> 8 | B9: CAM004 | C9: =IF(ISNA(VLOOKUP(B9, inventari!A:A, 1, FALSE)), "EQUIP_NO_EXISTEIX", "ID_VALID") -> ID_VALID | D9: =IF(C9="ID_VALID", VLOOKUP(B9, inventari!A:E, 5, FALSE), "N/A") -> MAGATZEM | E9: EMP016 - Eva Torres (Marketing) | F9: Càmera no enfoca | G9: 4 | H9: Urgent (afecta productivitat) | I9: 45712.698 | J9: CADUCADA | K9: =IF(C9="EQUIP_NO_EXISTEIX", "ERROR_EQUIP", IF(J9="VIGENT", "PENDENT_GARANTIA", "PENDENT_REVISAR")) -> PENDENT_REVISAR
